<?xml version="1.0"?>
<!-- 
PROFESSIONAL DEBUGGING DEMONSTRATION ROBOT
This URDF demonstrates advanced debugging concepts and solutions
that robotics engineers encounter in real-world projects.

DEBUGGING LESSONS DEMONSTRATED:
1. Coordinate System Issues → Proper wheel orientation and joint axes
2. Joint Type Mismatches → Continuous vs. revolute vs. prismatic
3. Kinematic Chain Errors → Proper parent-child relationships
4. Physical Properties → Realistic mass, inertia, and dynamics
5. Safety Systems → Proper limits, effort, and velocity constraints
6. Sensor Integration → Realistic sensor placement and modeling
7. Advanced Mechanisms → Professional actuator and feedback systems
-->

<robot name="broken_wheeled_robot">

  <!-- FIXED: Advanced Base Platform with Professional Design -->
  <link name="base_platform">
    <!-- Main chassis structure -->
    <visual>
      <origin xyz="0 0 0.08" rpy="0 0 0"/>
      <geometry>
        <box size="0.8 0.5 0.16"/>
      </geometry>
      <material name="chassis_professional">
        <color rgba="0.4 0.4 0.5 1.0"/>
      </material>
    </visual>
    
    <!-- Reinforcement ribs (DEBUGGING: Structural integrity) -->
    <visual>
      <origin xyz="0.35 0 0.08" rpy="0 0 0"/>
      <geometry>
        <box size="0.1 0.5 0.02"/>
      </geometry>
      <material name="reinforcement">
        <color rgba="0.6 0.6 0.7 1.0"/>
      </material>
    </visual>
    
    <visual>
      <origin xyz="-0.35 0 0.08" rpy="0 0 0"/>
      <geometry>
        <box size="0.1 0.5 0.02"/>
      </geometry>
      <material name="reinforcement">
        <color rgba="0.6 0.6 0.7 1.0"/>
      </material>
    </visual>
    
    <!-- Safety bumpers (DEBUGGING: Collision detection) -->
    <visual>
      <origin xyz="0.42 0 0.05" rpy="0 0 0"/>
      <geometry>
        <box size="0.04 0.5 0.1"/>
      </geometry>
      <material name="safety_yellow">
        <color rgba="1.0 0.9 0.0 1.0"/>
      </material>
    </visual>
    
    <visual>
      <origin xyz="-0.42 0 0.05" rpy="0 0 0"/>
      <geometry>
        <box size="0.04 0.5 0.1"/>
      </geometry>
      <material name="safety_orange">
        <color rgba="1.0 0.5 0.0 1.0"/>
      </material>
    </visual>
    
    <!-- Diagnostic LED array (DEBUGGING: Status monitoring) -->
    <visual>
      <origin xyz="0.35 0.2 0.17" rpy="0 0 0"/>
      <geometry>
        <cylinder radius="0.008" length="0.004"/>
      </geometry>
      <material name="led_power">
        <color rgba="0.0 1.0 0.0 1.0"/>
      </material>
    </visual>
    
    <visual>
      <origin xyz="0.35 0.13 0.17" rpy="0 0 0"/>
      <geometry>
        <cylinder radius="0.008" length="0.004"/>
      </geometry>
      <material name="led_network">
        <color rgba="0.0 0.4 1.0 1.0"/>
      </material>
    </visual>
    
    <visual>
      <origin xyz="0.35 0.06 0.17" rpy="0 0 0"/>
      <geometry>
        <cylinder radius="0.008" length="0.004"/>
      </geometry>
      <material name="led_motion">
        <color rgba="1.0 1.0 0.0 1.0"/>
      </material>
    </visual>
    
    <visual>
      <origin xyz="0.35 -0.01 0.17" rpy="0 0 0"/>
      <geometry>
        <cylinder radius="0.008" length="0.004"/>
      </geometry>
      <material name="led_error">
        <color rgba="1.0 0.0 0.0 1.0"/>
      </material>
    </visual>
    
    <!-- Emergency stop system (DEBUGGING: Safety systems) -->
    <visual>
      <origin xyz="0.3 0.18 0.18" rpy="0 0 0"/>
      <geometry>
        <cylinder radius="0.025" length="0.02"/>
      </geometry>
      <material name="emergency_stop">
        <color rgba="1.0 0.0 0.0 1.0"/>
      </material>
    </visual>
    
    <!-- Advanced battery system (DEBUGGING: Power management) -->
    <visual>
      <origin xyz="-0.2 0 0.18" rpy="0 0 0"/>
      <geometry>
        <box size="0.3 0.2 0.06"/>
      </geometry>
      <material name="battery_lithium">
        <color rgba="0.1 0.1 0.15 1.0"/>
      </material>
    </visual>
    
    <!-- Cooling system (DEBUGGING: Thermal management) -->
    <visual>
      <origin xyz="-0.2 0.12 0.18" rpy="0 0 0"/>
      <geometry>
        <box size="0.25 0.02 0.04"/>
      </geometry>
      <material name="cooling_vents">
        <color rgba="0.05 0.05 0.05 1.0"/>
      </material>
    </visual>
    
    <visual>
      <origin xyz="-0.2 -0.12 0.18" rpy="0 0 0"/>
      <geometry>
        <box size="0.25 0.02 0.04"/>
      </geometry>
      <material name="cooling_vents">
        <color rgba="0.05 0.05 0.05 1.0"/>
      </material>
    </visual>
    
    <!-- Onboard computer (DEBUGGING: Computing systems) -->
    <visual>
      <origin xyz="0.1 0 0.18" rpy="0 0 0"/>
      <geometry>
        <box size="0.2 0.12 0.04"/>
      </geometry>
      <material name="computer_housing">
        <color rgba="0.7 0.7 0.8 1.0"/>
      </material>
    </visual>
    
    <collision>
      <origin xyz="0 0 0.08" rpy="0 0 0"/>
      <geometry>
        <box size="0.8 0.5 0.16"/>
      </geometry>
    </collision>
    <inertial>
      <origin xyz="0 0 0.08" rpy="0 0 0"/>
      <mass value="35.0"/>
      <!-- FIXED: Realistic inertia for professional platform -->
      <inertia ixx="2.0" ixy="0" ixz="0" 
               iyy="3.5" iyz="0" 
               izz="4.8"/>
    </inertial>
  </link>

  <!-- FIXED: Professional Drive Wheels with Proper Orientation -->
  <link name="left_drive_wheel">
    <!-- SOLUTION: Proper wheel orientation rpy="1.57 0 0" -->
    <visual>
      <origin xyz="0 0 0" rpy="1.57 0 0"/>
      <geometry>
        <cylinder radius="0.15" length="0.08"/>
      </geometry>
      <material name="tire_professional">
        <color rgba="0.1 0.1 0.1 1.0"/>
      </material>
    </visual>
    
    <!-- Advanced rim design (DEBUGGING: Visual realism) -->
    <visual>
      <origin xyz="0 0 0" rpy="1.57 0 0"/>
      <geometry>
        <cylinder radius="0.12" length="0.085"/>
      </geometry>
      <material name="rim_aluminum">
        <color rgba="0.7 0.7 0.8 1.0"/>
      </material>
    </visual>
    
    <!-- Hub motor integration (DEBUGGING: Realistic mechanisms) -->
    <visual>
      <origin xyz="0 0 0" rpy="1.57 0 0"/>
      <geometry>
        <cylinder radius="0.07" length="0.09"/>
      </geometry>
      <material name="hub_motor">
        <color rgba="0.3 0.3 0.4 1.0"/>
      </material>
    </visual>
    
    <!-- Brake disc (DEBUGGING: Safety systems) -->
    <visual>
      <origin xyz="0 0 0.05" rpy="1.57 0 0"/>
      <geometry>
        <cylinder radius="0.1" length="0.008"/>
      </geometry>
      <material name="brake_disc">
        <color rgba="0.4 0.4 0.5 1.0"/>
      </material>
    </visual>
    
    <!-- Wheel encoder (DEBUGGING: Feedback systems) -->
    <visual>
      <origin xyz="0 0 0.048" rpy="1.57 0 0"/>
      <geometry>
        <cylinder radius="0.08" length="0.004"/>
      </geometry>
      <material name="encoder_gold">
        <color rgba="0.8 0.7 0.2 1.0"/>
      </material>
    </visual>
    
    <!-- SOLUTION: Proper collision geometry matching visual -->
    <collision>
      <origin xyz="0 0 0" rpy="1.57 0 0"/>
      <geometry>
        <cylinder radius="0.15" length="0.08"/>
      </geometry>
    </collision>
    <inertial>
      <origin xyz="0 0 0" rpy="0 0 0"/>
      <!-- FIXED: Realistic wheel mass and inertia -->
      <mass value="8.5"/>
      <inertia ixx="0.08" ixy="0" ixz="0" 
               iyy="0.08" iyz="0" 
               izz="0.08"/>
    </inertial>
  </link>

  <!-- FIXED: Right wheel identical to left (consistent design) -->
  <link name="right_drive_wheel">
    <visual>
      <origin xyz="0 0 0" rpy="1.57 0 0"/>
      <geometry>
        <cylinder radius="0.15" length="0.08"/>
      </geometry>
      <material name="tire_professional">
        <color rgba="0.1 0.1 0.1 1.0"/>
      </material>
    </visual>
    <visual>
      <origin xyz="0 0 0" rpy="1.57 0 0"/>
      <geometry>
        <cylinder radius="0.12" length="0.085"/>
      </geometry>
      <material name="rim_aluminum">
        <color rgba="0.7 0.7 0.8 1.0"/>
      </material>
    </visual>
    <visual>
      <origin xyz="0 0 0" rpy="1.57 0 0"/>
      <geometry>
        <cylinder radius="0.07" length="0.09"/>
      </geometry>
      <material name="hub_motor">
        <color rgba="0.3 0.3 0.4 1.0"/>
      </material>
    </visual>
    <visual>
      <origin xyz="0 0 0.05" rpy="1.57 0 0"/>
      <geometry>
        <cylinder radius="0.1" length="0.008"/>
      </geometry>
      <material name="brake_disc">
        <color rgba="0.4 0.4 0.5 1.0"/>
      </material>
    </visual>
    <visual>
      <origin xyz="0 0 0.048" rpy="1.57 0 0"/>
      <geometry>
        <cylinder radius="0.08" length="0.004"/>
      </geometry>
      <material name="encoder_gold">
        <color rgba="0.8 0.7 0.2 1.0"/>
      </material>
    </visual>
    <collision>
      <origin xyz="0 0 0" rpy="1.57 0 0"/>
      <geometry>
        <cylinder radius="0.15" length="0.08"/>
      </geometry>
    </collision>
    <inertial>
      <origin xyz="0 0 0" rpy="0 0 0"/>
      <mass value="8.5"/>
      <inertia ixx="0.08" ixy="0" ixz="0" 
               iyy="0.08" iyz="0" 
               izz="0.08"/>
    </inertial>
  </link>

  <!-- FIXED: Professional Lifting System Base -->
  <link name="hydraulic_lift_base">
    <!-- Main lift tower -->
    <visual>
      <origin xyz="0 0 0.12" rpy="0 0 0"/>
      <geometry>
        <box size="0.3 0.3 0.24"/>
      </geometry>
      <material name="lift_industrial">
        <color rgba="1.0 0.5 0.1 1.0"/>
      </material>
    </visual>
    
    <!-- Hydraulic cylinder housings (DEBUGGING: Realistic mechanisms) -->
    <visual>
      <origin xyz="0.1 0.1 0.12" rpy="0 0 0"/>
      <geometry>
        <cylinder radius="0.03" length="0.24"/>
      </geometry>
      <material name="hydraulic_steel">
        <color rgba="0.4 0.4 0.5 1.0"/>
      </material>
    </visual>
    
    <visual>
      <origin xyz="-0.1 0.1 0.12" rpy="0 0 0"/>
      <geometry>
        <cylinder radius="0.03" length="0.24"/>
      </geometry>
      <material name="hydraulic_steel">
        <color rgba="0.4 0.4 0.5 1.0"/>
      </material>
    </visual>
    
    <visual>
      <origin xyz="0.1 -0.1 0.12" rpy="0 0 0"/>
      <geometry>
        <cylinder radius="0.03" length="0.24"/>
      </geometry>
      <material name="hydraulic_steel">
        <color rgba="0.4 0.4 0.5 1.0"/>
      </material>
    </visual>
    
    <visual>
      <origin xyz="-0.1 -0.1 0.12" rpy="0 0 0"/>
      <geometry>
        <cylinder radius="0.03" length="0.24"/>
      </geometry>
      <material name="hydraulic_steel">
        <color rgba="0.4 0.4 0.5 1.0"/>
      </material>
    </visual>
    
    <!-- Precision guide rails (DEBUGGING: Linear motion guidance) -->
    <visual>
      <origin xyz="0.13 0 0.12" rpy="0 0 0"/>
      <geometry>
        <box size="0.04 0.04 0.24"/>
      </geometry>
      <material name="guide_rail">
        <color rgba="0.6 0.6 0.7 1.0"/>
      </material>
    </visual>
    
    <visual>
      <origin xyz="-0.13 0 0.12" rpy="0 0 0"/>
      <geometry>
        <box size="0.04 0.04 0.24"/>
      </geometry>
      <material name="guide_rail">
        <color rgba="0.6 0.6 0.7 1.0"/>
      </material>
    </visual>
    
    <!-- Safety warning strips (DEBUGGING: Safety visualization) -->
    <visual>
      <origin xyz="0 0.16 0.12" rpy="0 0 0"/>
      <geometry>
        <box size="0.25 0.02 0.2"/>
      </geometry>
      <material name="warning_stripes">
        <color rgba="1.0 1.0 0.0 1.0"/>
      </material>
    </visual>
    
    <visual>
      <origin xyz="0 -0.16 0.12" rpy="0 0 0"/>
      <geometry>
        <box size="0.25 0.02 0.2"/>
      </geometry>
      <material name="warning_stripes">
        <color rgba="1.0 1.0 0.0 1.0"/>
      </material>
    </visual>
    
    <!-- Hydraulic reservoir (DEBUGGING: System components) -->
    <visual>
      <origin xyz="-0.18 0 0.08" rpy="0 0 0"/>
      <geometry>
        <cylinder radius="0.06" length="0.16"/>
      </geometry>
      <material name="reservoir">
        <color rgba="0.2 0.2 0.3 1.0"/>
      </material>
    </visual>
    
    <!-- Control valves (DEBUGGING: Control systems) -->
    <visual>
      <origin xyz="0.18 0.08 0.08" rpy="0 0 0"/>
      <geometry>
        <box size="0.06 0.04 0.08"/>
      </geometry>
      <material name="valve_brass">
        <color rgba="0.8 0.7 0.3 1.0"/>
      </material>
    </visual>
    
    <visual>
      <origin xyz="0.18 -0.08 0.08" rpy="0 0 0"/>
      <geometry>
        <box size="0.06 0.04 0.08"/>
      </geometry>
      <material name="valve_brass">
        <color rgba="0.8 0.7 0.3 1.0"/>
      </material>
    </visual>
    
    <collision>
      <origin xyz="0 0 0.12" rpy="0 0 0"/>
      <geometry>
        <box size="0.3 0.3 0.24"/>
      </geometry>
    </collision>
    <inertial>
      <origin xyz="0 0 0.12" rpy="0 0 0"/>
      <!-- FIXED: Realistic mass for hydraulic system -->
      <mass value="25.0"/>
      <inertia ixx="0.3" ixy="0" ixz="0" 
               iyy="0.3" iyz="0" 
               izz="0.5"/>
    </inertial>
  </link>

  <!-- FIXED: Advanced Lifting Platform -->
  <link name="cargo_platform">
    <!-- Main platform deck -->
    <visual>
      <origin xyz="0 0 0.03" rpy="0 0 0"/>
      <geometry>
        <box size="0.4 0.4 0.06"/>
      </geometry>
      <material name="platform_deck">
        <color rgba="0.2 0.7 0.3 1.0"/>
      </material>
    </visual>
    
    <!-- Anti-slip surface (DEBUGGING: Safety features) -->
    <visual>
      <origin xyz="0 0 0.063" rpy="0 0 0"/>
      <geometry>
        <box size="0.38 0.38 0.006"/>
      </geometry>
      <material name="anti_slip">
        <color rgba="0.1 0.1 0.1 1.0"/>
      </material>
    </visual>
    
    <!-- Load securing points (DEBUGGING: Cargo handling) -->
    <visual>
      <origin xyz="0.15 0.15 0.07" rpy="0 0 0"/>
      <geometry>
        <cylinder radius="0.01" length="0.02"/>
      </geometry>
      <material name="tie_down_point">
        <color rgba="0.6 0.6 0.7 1.0"/>
      </material>
    </visual>
    
    <visual>
      <origin xyz="-0.15 0.15 0.07" rpy="0 0 0"/>
      <geometry>
        <cylinder radius="0.01" length="0.02"/>
      </geometry>
      <material name="tie_down_point">
        <color rgba="0.6 0.6 0.7 1.0"/>
      </material>
    </visual>
    
    <visual>
      <origin xyz="0.15 -0.15 0.07" rpy="0 0 0"/>
      <geometry>
        <cylinder radius="0.01" length="0.02"/>
      </geometry>
      <material name="tie_down_point">
        <color rgba="0.6 0.6 0.7 1.0"/>
      </material>
    </visual>
    
    <visual>
      <origin xyz="-0.15 -0.15 0.07" rpy="0 0 0"/>
      <geometry>
        <cylinder radius="0.01" length="0.02"/>
      </geometry>
      <material name="tie_down_point">
        <color rgba="0.6 0.6 0.7 1.0"/>
      </material>
    </visual>
    
    <!-- Hydraulic pistons (DEBUGGING: Actuator visualization) -->
    <visual>
      <origin xyz="0.1 0.1 -0.08" rpy="0 0 0"/>
      <geometry>
        <cylinder radius="0.02" length="0.16"/>
      </geometry>
      <material name="piston_chrome">
        <color rgba="0.8 0.8 0.9 1.0"/>
      </material>
    </visual>
    
    <visual>
      <origin xyz="-0.1 0.1 -0.08" rpy="0 0 0"/>
      <geometry>
        <cylinder radius="0.02" length="0.16"/>
      </geometry>
      <material name="piston_chrome">
        <color rgba="0.8 0.8 0.9 1.0"/>
      </material>
    </visual>
    
    <visual>
      <origin xyz="0.1 -0.1 -0.08" rpy="0 0 0"/>
      <geometry>
        <cylinder radius="0.02" length="0.16"/>
      </geometry>
      <material name="piston_chrome">
        <color rgba="0.8 0.8 0.9 1.0"/>
      </material>
    </visual>
    
    <visual>
      <origin xyz="-0.1 -0.1 -0.08" rpy="0 0 0"/>
      <geometry>
        <cylinder radius="0.02" length="0.16"/>
      </geometry>
      <material name="piston_chrome">
        <color rgba="0.8 0.8 0.9 1.0"/>
      </material>
    </visual>
    
    <!-- Platform safety lighting (DEBUGGING: Safety systems) -->
    <visual>
      <origin xyz="0.21 0 0.04" rpy="0 1.57 0"/>
      <geometry>
        <cylinder radius="0.008" length="0.012"/>
      </geometry>
      <material name="safety_led_red">
        <color rgba="1.0 0.0 0.0 1.0"/>
      </material>
    </visual>
    
    <visual>
      <origin xyz="-0.21 0 0.04" rpy="0 1.57 0"/>
      <geometry>
        <cylinder radius="0.008" length="0.012"/>
      </geometry>
      <material name="safety_led_red">
        <color rgba="1.0 0.0 0.0 1.0"/>
      </material>
    </visual>
    
    <visual>
      <origin xyz="0 0.21 0.04" rpy="1.57 0 0"/>
      <geometry>
        <cylinder radius="0.008" length="0.012"/>
      </geometry>
      <material name="safety_led_red">
        <color rgba="1.0 0.0 0.0 1.0"/>
      </material>
    </visual>
    
    <visual>
      <origin xyz="0 -0.21 0.04" rpy="1.57 0 0"/>
      <geometry>
        <cylinder radius="0.008" length="0.012"/>
      </geometry>
      <material name="safety_led_red">
        <color rgba="1.0 0.0 0.0 1.0"/>
      </material>
    </visual>
    
    <!-- Load cell sensors (DEBUGGING: Weight sensing) -->
    <visual>
      <origin xyz="0.12 0.12 0" rpy="0 0 0"/>
      <geometry>
        <cylinder radius="0.015" length="0.01"/>
      </geometry>
      <material name="load_cell">
        <color rgba="0.7 0.7 0.8 1.0"/>
      </material>
    </visual>
    
    <visual>
      <origin xyz="-0.12 0.12 0" rpy="0 0 0"/>
      <geometry>
        <cylinder radius="0.015" length="0.01"/>
      </geometry>
      <material name="load_cell">
        <color rgba="0.7 0.7 0.8 1.0"/>
      </material>
    </visual>
    
    <visual>
      <origin xyz="0.12 -0.12 0" rpy="0 0 0"/>
      <geometry>
        <cylinder radius="0.015" length="0.01"/>
      </geometry>
      <material name="load_cell">
        <color rgba="0.7 0.7 0.8 1.0"/>
      </material>
    </visual>
    
    <visual>
      <origin xyz="-0.12 -0.12 0" rpy="0 0 0"/>
      <geometry>
        <cylinder radius="0.015" length="0.01"/>
      </geometry>
      <material name="load_cell">
        <color rgba="0.7 0.7 0.8 1.0"/>
      </material>
    </visual>
    
    <collision>
      <origin xyz="0 0 0.03" rpy="0 0 0"/>
      <geometry>
        <box size="0.4 0.4 0.06"/>
      </geometry>
    </collision>
    <inertial>
      <origin xyz="0 0 0.03" rpy="0 0 0"/>
      <!-- FIXED: Realistic platform mass -->
      <mass value="12.0"/>
      <inertia ixx="0.2" ixy="0" ixz="0" 
               iyy="0.2" iyz="0" 
               izz="0.35"/>
    </inertial>
  </link>

  <!-- Advanced Sensor Suite -->
  
  <!-- 2D LIDAR Scanner (DEBUGGING: Navigation sensors) -->
  <link name="navigation_lidar">
    <visual>
      <origin xyz="0 0 0.04" rpy="0 0 0"/>
      <geometry>
        <cylinder radius="0.06" length="0.08"/>
      </geometry>
      <material name="lidar_housing">
        <color rgba="0.05 0.05 0.08 1.0"/>
      </material>
    </visual>
    
    <!-- Spinning mirror assembly -->
    <visual>
      <origin xyz="0 0 0.085" rpy="0 0 0"/>
      <geometry>
        <cylinder radius="0.05" length="0.01"/>
      </geometry>
      <material name="mirror_assembly">
        <color rgba="0.8 0.8 0.9 1.0"/>
      </material>
    </visual>
    
    <collision>
      <origin xyz="0 0 0.04" rpy="0 0 0"/>
      <geometry>
        <cylinder radius="0.06" length="0.08"/>
      </geometry>
    </collision>
    <inertial>
      <origin xyz="0 0 0.04" rpy="0 0 0"/>
      <mass value="1.2"/>
      <inertia ixx="0.004" ixy="0" ixz="0" 
               iyy="0.004" iyz="0" 
               izz="0.003"/>
    </inertial>
  </link>

  <!-- Ultrasonic sensor array (DEBUGGING: Proximity detection) -->
  <link name="ultrasonic_front_left">
    <visual>
      <origin xyz="0 0 0.01" rpy="0 0 0"/>
      <geometry>
        <cylinder radius="0.015" length="0.02"/>
      </geometry>
      <material name="ultrasonic_silver">
        <color rgba="0.7 0.7 0.8 1.0"/>
      </material>
    </visual>
    
    <collision>
      <origin xyz="0 0 0.01" rpy="0 0 0"/>
      <geometry>
        <cylinder radius="0.015" length="0.02"/>
      </geometry>
    </collision>
    <inertial>
      <origin xyz="0 0 0.01" rpy="0 0 0"/>
      <mass value="0.05"/>
      <inertia ixx="0.00001" ixy="0" ixz="0" 
               iyy="0.00001" iyz="0" 
               izz="0.00001"/>
    </inertial>
  </link>

  <link name="ultrasonic_front_right">
    <visual>
      <origin xyz="0 0 0.01" rpy="0 0 0"/>
      <geometry>
        <cylinder radius="0.015" length="0.02"/>
      </geometry>
      <material name="ultrasonic_silver">
        <color rgba="0.7 0.7 0.8 1.0"/>
      </material>
    </visual>
    
    <collision>
      <origin xyz="0 0 0.01" rpy="0 0 0"/>
      <geometry>
        <cylinder radius="0.015" length="0.02"/>
      </geometry>
    </collision>
    <inertial>
      <origin xyz="0 0 0.01" rpy="0 0 0"/>
      <mass value="0.05"/>
      <inertia ixx="0.00001" ixy="0" ixz="0" 
               iyy="0.00001" iyz="0" 
               izz="0.00001"/>
    </inertial>
  </link>

  <link name="ultrasonic_rear">
    <visual>
      <origin xyz="0 0 0.01" rpy="0 0 0"/>
      <geometry>
        <cylinder radius="0.015" length="0.02"/>
      </geometry>
      <material name="ultrasonic_silver">
        <color rgba="0.7 0.7 0.8 1.0"/>
      </material>
    </visual>
    
    <collision>
      <origin xyz="0 0 0.01" rpy="0 0 0"/>
      <geometry>
        <cylinder radius="0.015" length="0.02"/>
      </geometry>
    </collision>
    <inertial>
      <origin xyz="0 0 0.01" rpy="0 0 0"/>
      <mass value="0.05"/>
      <inertia ixx="0.00001" ixy="0" ixz="0" 
               iyy="0.00001" iyz="0" 
               izz="0.00001"/>
    </inertial>
  </link>

  <!-- JOINTS SECTION -->

  <!-- SOLUTION: Continuous wheel joints with correct axes -->
  <joint name="left_wheel_drive_joint" type="continuous">
    <parent link="base_platform"/>
    <child link="left_drive_wheel"/>
    <!-- FIXED: Proper wheel positioning -->
    <origin xyz="0 0.28 0" rpy="0 0 0"/>
    <!-- SOLUTION: Correct Y-axis for wheel rotation -->
    <axis xyz="0 1 0"/>
    <!-- FIXED: Professional wheel dynamics -->
    <dynamics damping="0.4" friction="0.3"/>
  </joint>

  <joint name="right_wheel_drive_joint" type="continuous">
    <parent link="base_platform"/>
    <child link="right_drive_wheel"/>
    <!-- FIXED: Proper wheel positioning -->
    <origin xyz="0 -0.28 0" rpy="0 0 0"/>
    <!-- SOLUTION: Correct Y-axis for wheel rotation -->
    <axis xyz="0 1 0"/>
    <!-- FIXED: Professional wheel dynamics -->
    <dynamics damping="0.4" friction="0.3"/>
  </joint>

  <!-- FIXED: Proper lift base mounting -->
  <joint name="lift_base_mount_joint" type="fixed">
    <parent link="base_platform"/>
    <child link="hydraulic_lift_base"/>
    <origin xyz="0 0 0.16" rpy="0 0 0"/>
  </joint>

  <!-- SOLUTION: Prismatic joint for linear lifting motion -->
  <joint name="hydraulic_lift_joint" type="prismatic">
    <parent link="hydraulic_lift_base"/>
    <child link="cargo_platform"/>
    <origin xyz="0 0 0.24" rpy="0 0 0"/>
    <!-- SOLUTION: Correct Z-axis for vertical lifting -->
    <axis xyz="0 0 1"/>
    <!-- FIXED: Professional lifting specifications -->
    <limit lower="0" upper="0.8" effort="2000" velocity="1.2"/>
    <!-- FIXED: Realistic hydraulic dynamics -->
    <dynamics damping="0.8" friction="0.5"/>
  </joint>

  <!-- Sensor mounting joints -->
  <joint name="lidar_mount_joint" type="fixed">
    <parent link="base_platform"/>
    <child link="navigation_lidar"/>
    <origin xyz="0.35 0 0.21" rpy="0 0 0"/>
  </joint>

  <joint name="ultrasonic_front_left_joint" type="fixed">
    <parent link="base_platform"/>
    <child link="ultrasonic_front_left"/>
    <origin xyz="0.4 0.15 0.12" rpy="0 0 0.3"/>
  </joint>

  <joint name="ultrasonic_front_right_joint" type="fixed">
    <parent link="base_platform"/>
    <child link="ultrasonic_front_right"/>
    <origin xyz="0.4 -0.15 0.12" rpy="0 0 -0.3"/>
  </joint>

  <joint name="ultrasonic_rear_joint" type="fixed">
    <parent link="base_platform"/>
    <child link="ultrasonic_rear"/>
    <origin xyz="-0.4 0 0.12" rpy="0 0 3.14159"/>
  </joint>

</robot>