<?xml version="1.0"?>
<robot name="enhanced_robot_arm">

  <!-- Advanced Research Platform Base -->
  <link name="base_link">
    <!-- Primary base platform with integrated cooling -->
    <visual>
      <origin xyz="0 0 0.06" rpy="0 0 0"/>
      <geometry>
        <cylinder radius="0.22" length="0.12"/>
      </geometry>
      <material name="base_aerospace_titanium">
        <color rgba="0.5 0.5 0.6 1.0"/>
      </material>
    </visual>
    
    <!-- Precision-machined anti-slip surface -->
    <visual>
      <origin xyz="0 0 0.125" rpy="0 0 0"/>
      <geometry>
        <cylinder radius="0.21" length="0.01"/>
      </geometry>
      <material name="grip_diamond_plate">
        <color rgba="0.25 0.25 0.25 1.0"/>
      </material>
    </visual>
    
    <!-- High-strength mounting bolts (8-point pattern) -->
    <visual>
      <origin xyz="0.15 0 0.125" rpy="0 0 0"/>
      <geometry>
        <cylinder radius="0.01" length="0.015"/>
      </geometry>
      <material name="bolt_titanium">
        <color rgba="0.6 0.6 0.7 1.0"/>
      </material>
    </visual>
    
    <visual>
      <origin xyz="0.106 0.106 0.125" rpy="0 0 0"/>
      <geometry>
        <cylinder radius="0.01" length="0.015"/>
      </geometry>
      <material name="bolt_titanium">
        <color rgba="0.6 0.6 0.7 1.0"/>
      </material>
    </visual>
    
    <visual>
      <origin xyz="0 0.15 0.125" rpy="0 0 0"/>
      <geometry>
        <cylinder radius="0.01" length="0.015"/>
      </geometry>
      <material name="bolt_titanium">
        <color rgba="0.6 0.6 0.7 1.0"/>
      </material>
    </visual>
    
    <visual>
      <origin xyz="-0.106 0.106 0.125" rpy="0 0 0"/>
      <geometry>
        <cylinder radius="0.01" length="0.015"/>
      </geometry>
      <material name="bolt_titanium">
        <color rgba="0.6 0.6 0.7 1.0"/>
      </material>
    </visual>
    
    <visual>
      <origin xyz="-0.15 0 0.125" rpy="0 0 0"/>
      <geometry>
        <cylinder radius="0.01" length="0.015"/>
      </geometry>
      <material name="bolt_titanium">
        <color rgba="0.6 0.6 0.7 1.0"/>
      </material>
    </visual>
    
    <visual>
      <origin xyz="-0.106 -0.106 0.125" rpy="0 0 0"/>
      <geometry>
        <cylinder radius="0.01" length="0.015"/>
      </geometry>
      <material name="bolt_titanium">
        <color rgba="0.6 0.6 0.7 1.0"/>
      </material>
    </visual>
    
    <visual>
      <origin xyz="0 -0.15 0.125" rpy="0 0 0"/>
      <geometry>
        <cylinder radius="0.01" length="0.015"/>
      </geometry>
      <material name="bolt_titanium">
        <color rgba="0.6 0.6 0.7 1.0"/>
      </material>
    </visual>
    
    <visual>
      <origin xyz="0.106 -0.106 0.125" rpy="0 0 0"/>
      <geometry>
        <cylinder radius="0.01" length="0.015"/>
      </geometry>
      <material name="bolt_titanium">
        <color rgba="0.6 0.6 0.7 1.0"/>
      </material>
    </visual>
    
    <!-- Advanced LED status system -->
    <visual>
      <origin xyz="0 0 0.135" rpy="0 0 0"/>
      <geometry>
        <cylinder radius="0.19" length="0.003"/>
      </geometry>
      <material name="led_ring_active">
        <color rgba="0.0 0.8 1.0 1.0"/>
      </material>
    </visual>
    
    <!-- Cooling system vents -->
    <visual>
      <origin xyz="0.18 0 0.06" rpy="0 0 0"/>
      <geometry>
        <box size="0.08 0.02 0.1"/>
      </geometry>
      <material name="vent_graphite">
        <color rgba="0.1 0.1 0.1 1.0"/>
      </material>
    </visual>
    
    <visual>
      <origin xyz="-0.18 0 0.06" rpy="0 0 0"/>
      <geometry>
        <box size="0.08 0.02 0.1"/>
      </geometry>
      <material name="vent_graphite">
        <color rgba="0.1 0.1 0.1 1.0"/>
      </material>
    </visual>
    
    <!-- Integrated power distribution -->
    <visual>
      <origin xyz="0 0.18 0.06" rpy="0 0 0"/>
      <geometry>
        <box size="0.12 0.06 0.08"/>
      </geometry>
      <material name="power_distribution">
        <color rgba="0.2 0.2 0.3 1.0"/>
      </material>
    </visual>
    
    <!-- Emergency stop integration -->
    <visual>
      <origin xyz="0.15 0.15 0.14" rpy="0 0 0"/>
      <geometry>
        <cylinder radius="0.025" length="0.02"/>
      </geometry>
      <material name="emergency_stop">
        <color rgba="1.0 0.0 0.0 1.0"/>
      </material>
    </visual>
    
    <collision>
      <origin xyz="0 0 0.06" rpy="0 0 0"/>
      <geometry>
        <cylinder radius="0.22" length="0.12"/>
      </geometry>
    </collision>
    <inertial>
      <origin xyz="0 0 0.06" rpy="0 0 0"/>
      <mass value="15.0"/>
      <inertia ixx="0.2" ixy="0" ixz="0" iyy="0.2" iyz="0" izz="0.35"/>
    </inertial>
  </link>

  <!-- Advanced Shoulder Assembly -->
  <link name="shoulder_link">
    <!-- Primary shoulder structure -->
    <visual>
      <origin xyz="0 0 0.125" rpy="0 0 0"/>
      <geometry>
        <cylinder radius="0.09" length="0.25"/>
      </geometry>
      <material name="arm_aerospace_blue">
        <color rgba="0.1 0.35 0.75 1.0"/>
      </material>
    </visual>
    
    <!-- Advanced cooling fins -->
    <visual>
      <origin xyz="0.095 0 0.125" rpy="0 1.57 0"/>
      <geometry>
        <box size="0.25 0.02 0.02"/>
      </geometry>
      <material name="cooling_aluminum">
        <color rgba="0.8 0.8 0.85 1.0"/>
      </material>
    </visual>
    
    <visual>
      <origin xyz="-0.095 0 0.125" rpy="0 1.57 0"/>
      <geometry>
        <box size="0.25 0.02 0.02"/>
      </geometry>
      <material name="cooling_aluminum">
        <color rgba="0.8 0.8 0.85 1.0"/>
      </material>
    </visual>
    
    <visual>
      <origin xyz="0 0.095 0.125" rpy="1.57 0 0"/>
      <geometry>
        <box size="0.02 0.25 0.02"/>
      </geometry>
      <material name="cooling_aluminum">
        <color rgba="0.8 0.8 0.85 1.0"/>
      </material>
    </visual>
    
    <visual>
      <origin xyz="0 -0.095 0.125" rpy="1.57 0 0"/>
      <geometry>
        <box size="0.02 0.25 0.02"/>
      </geometry>
      <material name="cooling_aluminum">
        <color rgba="0.8 0.8 0.85 1.0"/>
      </material>
    </visual>
    
    <!-- High-precision servo motor -->
    <visual>
      <origin xyz="0 0 0.26" rpy="0 0 0"/>
      <geometry>
        <cylinder radius="0.095" length="0.03"/>
      </geometry>
      <material name="servo_housing">
        <color rgba="0.05 0.05 0.08 1.0"/>
      </material>
    </visual>
    
    <!-- Integrated torque sensor -->
    <visual>
      <origin xyz="0 0 0.285" rpy="0 0 0"/>
      <geometry>
        <cylinder radius="0.08" length="0.01"/>
      </geometry>
      <material name="torque_sensor">
        <color rgba="0.7 0.7 0.8 1.0"/>
      </material>
    </visual>
    
    <!-- Advanced cable management -->
    <visual>
      <origin xyz="0.105 0 0.125" rpy="0 0 0"/>
      <geometry>
        <box size="0.025 0.04 0.25"/>
      </geometry>
      <material name="cable_carrier_advanced">
        <color rgba="0.15 0.15 0.15 1.0"/>
      </material>
    </visual>
    
    <!-- Temperature sensors -->
    <visual>
      <origin xyz="0.08 0.08 0.2" rpy="0 0 0"/>
      <geometry>
        <cylinder radius="0.005" length="0.01"/>
      </geometry>
      <material name="temp_sensor">
        <color rgba="0.8 0.2 0.2 1.0"/>
      </material>
    </visual>
    
    <visual>
      <origin xyz="-0.08 0.08 0.2" rpy="0 0 0"/>
      <geometry>
        <cylinder radius="0.005" length="0.01"/>
      </geometry>
      <material name="temp_sensor">
        <color rgba="0.8 0.2 0.2 1.0"/>
      </material>
    </visual>
    
    <collision>
      <origin xyz="0 0 0.125" rpy="0 0 0"/>
      <geometry>
        <cylinder radius="0.09" length="0.25"/>
      </geometry>
    </collision>
    <inertial>
      <origin xyz="0 0 0.125" rpy="0 0 0"/>
      <mass value="8.5"/>
      <inertia ixx="0.08" ixy="0" ixz="0" iyy="0.08" iyz="0" izz="0.04"/>
    </inertial>
  </link>

  <!-- Extended Reach Upper Arm -->
  <link name="upper_arm_link">
    <!-- Main arm structure -->
    <visual>
      <origin xyz="0 0 0.22" rpy="0 0 0"/>
      <geometry>
        <cylinder radius="0.075" length="0.44"/>
      </geometry>
      <material name="arm_aerospace_green">
        <color rgba="0.1 0.65 0.25 1.0"/>
      </material>
    </visual>
    
    <!-- Carbon fiber reinforcement -->
    <visual>
      <origin xyz="0 0 0.1" rpy="0 0 0"/>
      <geometry>
        <cylinder radius="0.078" length="0.03"/>
      </geometry>
      <material name="carbon_fiber">
        <color rgba="0.05 0.05 0.1 1.0"/>
      </material>
    </visual>
    
    <visual>
      <origin xyz="0 0 0.22" rpy="0 0 0"/>
      <geometry>
        <cylinder radius="0.078" length="0.03"/>
      </geometry>
      <material name="carbon_fiber">
        <color rgba="0.05 0.05 0.1 1.0"/>
      </material>
    </visual>
    
    <visual>
      <origin xyz="0 0 0.34" rpy="0 0 0"/>
      <geometry>
        <cylinder radius="0.078" length="0.03"/>
      </geometry>
      <material name="carbon_fiber">
        <color rgba="0.05 0.05 0.1 1.0"/>
      </material>
    </visual>
    
    <!-- High-torque servo actuator -->
    <visual>
      <origin xyz="0 0.1 0.22" rpy="1.57 0 0"/>
      <geometry>
        <cylinder radius="0.045" length="0.2"/>
      </geometry>
      <material name="servo_titanium">
        <color rgba="0.6 0.6 0.7 1.0"/>
      </material>
    </visual>
    
    <!-- Advanced position encoder -->
    <visual>
      <origin xyz="0 -0.1 0.22" rpy="1.57 0 0"/>
      <geometry>
        <cylinder radius="0.035" length="0.08"/>
      </geometry>
      <material name="encoder_precision">
        <color rgba="0.8 0.7 0.3 1.0"/>
      </material>
    </visual>
    
    <!-- Adaptive cable carrier -->
    <visual>
      <origin xyz="0.085 0 0.22" rpy="0 0 0"/>
      <geometry>
        <box size="0.025 0.05 0.44"/>
      </geometry>
      <material name="cable_carrier_flex">
        <color rgba="0.1 0.1 0.1 1.0"/>
      </material>
    </visual>
    
    <!-- Vibration dampeners -->
    <visual>
      <origin xyz="0.07 0.07 0.15" rpy="0 0 0"/>
      <geometry>
        <cylinder radius="0.008" length="0.02"/>
      </geometry>
      <material name="dampener">
        <color rgba="0.3 0.3 0.3 1.0"/>
      </material>
    </visual>
    
    <visual>
      <origin xyz="-0.07 0.07 0.15" rpy="0 0 0"/>
      <geometry>
        <cylinder radius="0.008" length="0.02"/>
      </geometry>
      <material name="dampener">
        <color rgba="0.3 0.3 0.3 1.0"/>
      </material>
    </visual>
    
    <visual>
      <origin xyz="0.07 -0.07 0.15" rpy="0 0 0"/>
      <geometry>
        <cylinder radius="0.008" length="0.02"/>
      </geometry>
      <material name="dampener">
        <color rgba="0.3 0.3 0.3 1.0"/>
      </material>
    </visual>
    
    <visual>
      <origin xyz="-0.07 -0.07 0.15" rpy="0 0 0"/>
      <geometry>
        <cylinder radius="0.008" length="0.02"/>
      </geometry>
      <material name="dampener">
        <color rgba="0.3 0.3 0.3 1.0"/>
      </material>
    </visual>
    
    <collision>
      <origin xyz="0 0 0.22" rpy="0 0 0"/>
      <geometry>
        <cylinder radius="0.075" length="0.44"/>
      </geometry>
    </collision>
    <inertial>
      <origin xyz="0 0 0.22" rpy="0 0 0"/>
      <mass value="6.8"/>
      <inertia ixx="0.15" ixy="0" ixz="0" iyy="0.15" iyz="0" izz="0.025"/>
    </inertial>
  </link>

  <!-- Advanced Forearm Assembly -->
  <link name="forearm_link">
    <!-- Main forearm structure -->
    <visual>
      <origin xyz="0 0 0.08" rpy="0 0 0"/>
      <geometry>
        <cylinder radius="0.055" length="0.16"/>
      </geometry>
      <material name="arm_aerospace_red">
        <color rgba="0.75 0.1 0.1 1.0"/>
      </material>
    </visual>
    
    <!-- Wrist assembly housing -->
    <visual>
      <origin xyz="0 0 0.17" rpy="0 0 0"/>
      <geometry>
        <cylinder radius="0.06" length="0.02"/>
      </geometry>
      <material name="wrist_housing">
        <color rgba="0.4 0.4 0.5 1.0"/>
      </material>
    </visual>
    
    <!-- Force/torque sensor -->
    <visual>
      <origin xyz="0 0 0.19" rpy="0 0 0"/>
      <geometry>
        <cylinder radius="0.05" length="0.02"/>
      </geometry>
      <material name="ft_sensor">
        <color rgba="0.8 0.8 0.9 1.0"/>
      </material>
    </visual>
    
    <!-- Tool interface plate -->
    <visual>
      <origin xyz="0 0 0.21" rpy="0 0 0"/>
      <geometry>
        <cylinder radius="0.045" length="0.02"/>
      </geometry>
      <material name="tool_interface">
        <color rgba="0.9 0.8 0.4 1.0"/>
      </material>
    </visual>
    
    <!-- Pneumatic/hydraulic connections -->
    <visual>
      <origin xyz="0.045 0 0.12" rpy="0 1.57 0"/>
      <geometry>
        <cylinder radius="0.008" length="0.02"/>
      </geometry>
      <material name="pneumatic_blue">
        <color rgba="0.0 0.4 0.8 1.0"/>
      </material>
    </visual>
    
    <visual>
      <origin xyz="-0.045 0 0.12" rpy="0 1.57 0"/>
      <geometry>
        <cylinder radius="0.008" length="0.02"/>
      </geometry>
      <material name="pneumatic_red">
        <color rgba="0.8 0.0 0.0 1.0"/>
      </material>
    </visual>
    
    <visual>
      <origin xyz="0 0.045 0.12" rpy="1.57 0 0"/>
      <geometry>
        <cylinder radius="0.008" length="0.02"/>
      </geometry>
      <material name="hydraulic_gold">
        <color rgba="0.8 0.7 0.2 1.0"/>
      </material>
    </visual>
    
    <collision>
      <origin xyz="0 0 0.08" rpy="0 0 0"/>
      <geometry>
        <cylinder radius="0.055" length="0.16"/>
      </geometry>
    </collision>
    <inertial>
      <origin xyz="0 0 0.08" rpy="0 0 0"/>
      <mass value="3.5"/>
      <inertia ixx="0.008" ixy="0" ixz="0" iyy="0.008" iyz="0" izz="0.006"/>
    </inertial>
  </link>

  <!-- 6-DOF Wrist Assembly -->
  
  <!-- Wrist Roll Joint -->
  <link name="wrist_roll_link">
    <visual>
      <origin xyz="0 0 0.03" rpy="0 0 0"/>
      <geometry>
        <cylinder radius="0.04" length="0.06"/>
      </geometry>
      <material name="wrist_titanium">
        <color rgba="0.6 0.6 0.7 1.0"/>
      </material>
    </visual>
    
    <!-- Integrated encoder -->
    <visual>
      <origin xyz="0 0 0.065" rpy="0 0 0"/>
      <geometry>
        <cylinder radius="0.035" length="0.01"/>
      </geometry>
      <material name="encoder_ring">
        <color rgba="0.8 0.7 0.3 1.0"/>
      </material>
    </visual>
    
    <collision>
      <origin xyz="0 0 0.03" rpy="0 0 0"/>
      <geometry>
        <cylinder radius="0.04" length="0.06"/>
      </geometry>
    </collision>
    <inertial>
      <origin xyz="0 0 0.03" rpy="0 0 0"/>
      <mass value="1.8"/>
      <inertia ixx="0.003" ixy="0" ixz="0" iyy="0.003" iyz="0" izz="0.002"/>
    </inertial>
  </link>

  <!-- Wrist Pitch Joint -->
  <link name="wrist_pitch_link">
    <visual>
      <origin xyz="0 0 0.025" rpy="0 0 0"/>
      <geometry>
        <cylinder radius="0.035" length="0.05"/>
      </geometry>
      <material name="wrist_pitch">
        <color rgba="0.5 0.5 0.6 1.0"/>
      </material>
    </visual>
    
    <collision>
      <origin xyz="0 0 0.025" rpy="0 0 0"/>
      <geometry>
        <cylinder radius="0.035" length="0.05"/>
      </geometry>
    </collision>
    <inertial>
      <origin xyz="0 0 0.025" rpy="0 0 0"/>
      <mass value="1.2"/>
      <inertia ixx="0.002" ixy="0" ixz="0" iyy="0.002" iyz="0" izz="0.001"/>
    </inertial>
  </link>

  <!-- Wrist Yaw Joint -->
  <link name="wrist_yaw_link">
    <visual>
      <origin xyz="0 0 0.02" rpy="0 0 0"/>
      <geometry>
        <cylinder radius="0.03" length="0.04"/>
      </geometry>
      <material name="wrist_yaw">
        <color rgba="0.4 0.4 0.5 1.0"/>
      </material>
    </visual>
    
    <!-- Tool mounting interface -->
    <visual>
      <origin xyz="0 0 0.045" rpy="0 0 0"/>
      <geometry>
        <cylinder radius="0.032" length="0.01"/>
      </geometry>
      <material name="mount_interface">
        <color rgba="0.9 0.8 0.4 1.0"/>
      </material>
    </visual>
    
    <collision>
      <origin xyz="0 0 0.02" rpy="0 0 0"/>
      <geometry>
        <cylinder radius="0.03" length="0.04"/>
      </geometry>
    </collision>
    <inertial>
      <origin xyz="0 0 0.02" rpy="0 0 0"/>
      <mass value="0.8"/>
      <inertia ixx="0.001" ixy="0" ixz="0" iyy="0.001" iyz="0" izz="0.001"/>
    </inertial>
  </link>

  <!-- Advanced Smart Gripper System -->
  
  <!-- Smart Gripper Finger 1 -->
  <link name="gripper_finger_1">
    <!-- Advanced finger structure -->
    <visual>
      <origin xyz="0.035 0 0" rpy="0 1.57 0"/>
      <geometry>
        <cylinder radius="0.018" length="0.07"/>
      </geometry>
      <material name="gripper_aerospace">
        <color rgba="0.85 0.75 0.4 1.0"/>
      </material>
    </visual>
    
    <!-- Adaptive grip surface -->
    <visual>
      <origin xyz="0.072 0 0" rpy="0 1.57 0"/>
      <geometry>
        <cylinder radius="0.022" length="0.006"/>
      </geometry>
      <material name="adaptive_grip">
        <color rgba="0.05 0.05 0.08 1.0"/>
      </material>
    </visual>
    
    <!-- Integrated force/torque sensor -->
    <visual>
      <origin xyz="0.067 0 0" rpy="0 1.57 0"/>
      <geometry>
        <cylinder radius="0.015" length="0.01"/>
      </geometry>
      <material name="ft_sensor_crystal">
        <color rgba="0.8 0.9 1.0 1.0"/>
      </material>
    </visual>
    
    <!-- Tactile sensor array -->
    <visual>
      <origin xyz="0.063 0.018 0" rpy="0 1.57 0"/>
      <geometry>
        <cylinder radius="0.005" length="0.003"/>
      </geometry>
      <material name="tactile_sensor">
        <color rgba="0.0 0.8 0.2 1.0"/>
      </material>
    </visual>
    
    <visual>
      <origin xyz="0.063 -0.018 0" rpy="0 1.57 0"/>
      <geometry>
        <cylinder radius="0.005" length="0.003"/>
      </geometry>
      <material name="tactile_sensor">
        <color rgba="0.0 0.8 0.2 1.0"/>
      </material>
    </visual>
    
    <visual>
      <origin xyz="0.063 0 0.018" rpy="0 1.57 0"/>
      <geometry>
        <cylinder radius="0.005" length="0.003"/>
      </geometry>
      <material name="tactile_sensor">
        <color rgba="0.0 0.8 0.2 1.0"/>
      </material>
    </visual>
    
    <visual>
      <origin xyz="0.063 0 -0.018" rpy="0 1.57 0"/>
      <geometry>
        <cylinder radius="0.005" length="0.003"/>
      </geometry>
      <material name="tactile_sensor">
        <color rgba="0.0 0.8 0.2 1.0"/>
      </material>
    </visual>
    
    <!-- Proximity sensors -->
    <visual>
      <origin xyz="0.058 0.015 0" rpy="0 1.57 0"/>
      <geometry>
        <cylinder radius="0.003" length="0.002"/>
      </geometry>
      <material name="proximity_led">
        <color rgba="1.0 0.0 0.2 1.0"/>
      </material>
    </visual>
    
    <visual>
      <origin xyz="0.058 -0.015 0" rpy="0 1.57 0"/>
      <geometry>
        <cylinder radius="0.003" length="0.002"/>
      </geometry>
      <material name="proximity_led">
        <color rgba="1.0 0.0 0.2 1.0"/>
      </material>
    </visual>
    
    <!-- Advanced actuator -->
    <visual>
      <origin xyz="0.015 0 0" rpy="0 1.57 0"/>
      <geometry>
        <cylinder radius="0.012" length="0.03"/>
      </geometry>
      <material name="actuator_precision">
        <color rgba="0.8 0.8 0.9 1.0"/>
      </material>
    </visual>
    
    <collision>
      <origin xyz="0.035 0 0" rpy="0 1.57 0"/>
      <geometry>
        <cylinder radius="0.018" length="0.07"/>
      </geometry>
    </collision>
    <inertial>
      <origin xyz="0.035 0 0" rpy="0 0 0"/>
      <mass value="0.6"/>
      <inertia ixx="0.0008" ixy="0" ixz="0" iyy="0.0008" iyz="0" izz="0.0004"/>
    </inertial>
  </link>

  <!-- Smart Gripper Finger 2 -->
  <link name="gripper_finger_2">
    <!-- Advanced finger structure -->
    <visual>
      <origin xyz="-0.035 0 0" rpy="0 1.57 0"/>
      <geometry>
        <cylinder radius="0.018" length="0.07"/>
      </geometry>
      <material name="gripper_aerospace">
        <color rgba="0.85 0.75 0.4 1.0"/>
      </material>
    </visual>
    
    <!-- Adaptive grip surface -->
    <visual>
      <origin xyz="-0.072 0 0" rpy="0 1.57 0"/>
      <geometry>
        <cylinder radius="0.022" length="0.006"/>
      </geometry>
      <material name="adaptive_grip">
        <color rgba="0.05 0.05 0.08 1.0"/>
      </material>
    </visual>
    
    <!-- Integrated force/torque sensor -->
    <visual>
      <origin xyz="-0.067 0 0" rpy="0 1.57 0"/>
      <geometry>
        <cylinder radius="0.015" length="0.01"/>
      </geometry>
      <material name="ft_sensor_crystal">
        <color rgba="0.8 0.9 1.0 1.0"/>
      </material>
    </visual>
    
    <!-- Tactile sensor array -->
    <visual>
      <origin xyz="-0.063 0.018 0" rpy="0 1.57 0"/>
      <geometry>
        <cylinder radius="0.005" length="0.003"/>
      </geometry>
      <material name="tactile_sensor">
        <color rgba="0.0 0.8 0.2 1.0"/>
      </material>
    </visual>
    
    <visual>
      <origin xyz="-0.063 -0.018 0" rpy="0 1.57 0"/>
      <geometry>
        <cylinder radius="0.005" length="0.003"/>
      </geometry>
      <material name="tactile_sensor">
        <color rgba="0.0 0.8 0.2 1.0"/>
      </material>
    </visual>
    
    <visual>
      <origin xyz="-0.063 0 0.018" rpy="0 1.57 0"/>
      <geometry>
        <cylinder radius="0.005" length="0.003"/>
      </geometry>
      <material name="tactile_sensor">
        <color rgba="0.0 0.8 0.2 1.0"/>
      </material>
    </visual>
    
    <visual>
      <origin xyz="-0.063 0 -0.018" rpy="0 1.57 0"/>
      <geometry>
        <cylinder radius="0.005" length="0.003"/>
      </geometry>
      <material name="tactile_sensor">
        <color rgba="0.0 0.8 0.2 1.0"/>
      </material>
    </visual>
    
    <!-- Proximity sensors -->
    <visual>
      <origin xyz="-0.058 0.015 0" rpy="0 1.57 0"/>
      <geometry>
        <cylinder radius="0.003" length="0.002"/>
      </geometry>
      <material name="proximity_led">
        <color rgba="1.0 0.0 0.2 1.0"/>
      </material>
    </visual>
    
    <visual>
      <origin xyz="-0.058 -0.015 0" rpy="0 1.57 0"/>
      <geometry>
        <cylinder radius="0.003" length="0.002"/>
      </geometry>
      <material name="proximity_led">
        <color rgba="1.0 0.0 0.2 1.0"/>
      </material>
    </visual>
    
    <!-- Advanced actuator -->
    <visual>
      <origin xyz="-0.015 0 0" rpy="0 1.57 0"/>
      <geometry>
        <cylinder radius="0.012" length="0.03"/>
      </geometry>
      <material name="actuator_precision">
        <color rgba="0.8 0.8 0.9 1.0"/>
      </material>
    </visual>
    
    <collision>
      <origin xyz="-0.035 0 0" rpy="0 1.57 0"/>
      <geometry>
        <cylinder radius="0.018" length="0.07"/>
      </geometry>
    </collision>
    <inertial>
      <origin xyz="-0.035 0 0" rpy="0 0 0"/>
      <mass value="0.6"/>
      <inertia ixx="0.0008" ixy="0" ixz="0" iyy="0.0008" iyz="0" izz="0.0004"/>
    </inertial>
  </link>

  <!-- Advanced Sensor Suite -->
  
  <!-- Wrist-mounted camera -->
  <link name="wrist_camera">
    <visual>
      <origin xyz="0 0 0.01" rpy="0 0 0"/>
      <geometry>
        <box size="0.03 0.02 0.02"/>
      </geometry>
      <material name="camera_housing">
        <color rgba="0.05 0.05 0.08 1.0"/>
      </material>
    </visual>
    
    <!-- Camera lens -->
    <visual>
      <origin xyz="0.016 0 0.01" rpy="0 1.57 0"/>
      <geometry>
        <cylinder radius="0.006" length="0.002"/>
      </geometry>
      <material name="camera_lens">
        <color rgba="0.1 0.1 0.15 1.0"/>
      </material>
    </visual>
    
    <collision>
      <origin xyz="0 0 0.01" rpy="0 0 0"/>
      <geometry>
        <box size="0.03 0.02 0.02"/>
      </geometry>
    </collision>
    <inertial>
      <origin xyz="0 0 0.01" rpy="0 0 0"/>
      <mass value="0.1"/>
      <inertia ixx="0.00005" ixy="0" ixz="0" iyy="0.00008" iyz="0" izz="0.00005"/>
    </inertial>
  </link>

  <!-- JOINTS SECTION -->

  <!-- Base Joint - High-Precision Research Grade -->
  <joint name="base_joint" type="revolute">
    <parent link="base_link"/>
    <child link="shoulder_link"/>
    <origin xyz="0 0 0.13" rpy="0 0 0"/>
    <axis xyz="0 0 1"/>
    <limit lower="-6.28318" upper="6.28318" effort="400" velocity="4.0"/>
    <dynamics damping="0.8" friction="0.4"/>
  </joint>

  <!-- Shoulder Joint - High-Torque Research Grade -->
  <joint name="shoulder_joint" type="revolute">
    <parent link="shoulder_link"/>
    <child link="upper_arm_link"/>
    <origin xyz="0 0 0.29" rpy="0 0 0"/>
    <axis xyz="0 1 0"/>
    <limit lower="-2.8" upper="2.8" effort="300" velocity="3.5"/>
    <dynamics damping="0.8" friction="0.4"/>
  </joint>

  <!-- Elbow Joint - Extended Range Research Grade -->
  <joint name="elbow_joint" type="revolute">
    <parent link="upper_arm_link"/>
    <child link="forearm_link"/>
    <origin xyz="0 0 0.44" rpy="0 0 0"/>
    <axis xyz="0 1 0"/>
    <limit lower="-3.2" upper="3.2" effort="200" velocity="4.0"/>
    <dynamics damping="0.6" friction="0.3"/>
  </joint>

  <!-- Wrist Roll Joint - Continuous Research Grade -->
  <joint name="wrist_roll_joint" type="continuous">
    <parent link="forearm_link"/>
    <child link="wrist_roll_link"/>
    <origin xyz="0 0 0.22" rpy="0 0 0"/>
    <axis xyz="0 0 1"/>
    <dynamics damping="0.3" friction="0.15"/>
  </joint>

  <!-- Wrist Pitch Joint - High-Speed Research Grade -->
  <joint name="wrist_pitch_joint" type="revolute">
    <parent link="wrist_roll_link"/>
    <child link="wrist_pitch_link"/>
    <origin xyz="0 0 0.07" rpy="0 0 0"/>
    <axis xyz="0 1 0"/>
    <limit lower="-2.2" upper="2.2" effort="120" velocity="5.0"/>
    <dynamics damping="0.3" friction="0.15"/>
  </joint>

  <!-- Wrist Yaw Joint - Ultra-Precision Research Grade -->
  <joint name="wrist_yaw_joint" type="revolute">
    <parent link="wrist_pitch_link"/>
    <child link="wrist_yaw_link"/>
    <origin xyz="0 0 0.05" rpy="0 0 0"/>
    <axis xyz="1 0 0"/>
    <limit lower="-2.2" upper="2.2" effort="80" velocity="5.0"/>
    <dynamics damping="0.2" friction="0.1"/>
  </joint>

  <!-- Advanced Gripper Joints -->
  <joint name="gripper_joint_1" type="prismatic">
    <parent link="wrist_yaw_link"/>
    <child link="gripper_finger_1"/>
    <origin xyz="0 0 0.05" rpy="0 0 0"/>
    <axis xyz="1 0 0"/>
    <limit lower="0" upper="0.1" effort="100" velocity="1.5"/>
    <dynamics damping="0.3" friction="0.15"/>
  </joint>

  <joint name="gripper_joint_2" type="prismatic">
    <parent link="wrist_yaw_link"/>
    <child link="gripper_finger_2"/>
    <origin xyz="0 0 0.05" rpy="0 0 0"/>
    <axis xyz="1 0 0"/>
    <limit lower="-0.1" upper="0" effort="100" velocity="1.5"/>
    <dynamics damping="0.3" friction="0.15"/>
  </joint>

  <!-- Sensor Mounts -->
  <joint name="wrist_camera_joint" type="fixed">
    <parent link="wrist_yaw_link"/>
    <child link="wrist_camera"/>
    <origin xyz="0 0.04 0.03" rpy="0 0 0"/>
  </joint>

</robot>