<?xml version="1.0"?>
<robot name="wheeled_robot">

  <!-- Industrial Base Platform with Advanced Features -->
  <link name="base_link">
    <!-- Main chassis structure -->
    <visual>
      <origin xyz="0 0 0.06" rpy="0 0 0"/>
      <geometry>
        <box size="0.7 0.4 0.12"/>
      </geometry>
      <material name="chassis_industrial">
        <color rgba="0.4 0.4 0.5 1.0"/>
      </material>
    </visual>
    
    <!-- Reinforcement frame -->
    <visual>
      <origin xyz="0.32 0 0.06" rpy="0 0 0"/>
      <geometry>
        <box size="0.06 0.4 0.02"/>
      </geometry>
      <material name="frame_steel">
        <color rgba="0.6 0.6 0.7 1.0"/>
      </material>
    </visual>
    
    <visual>
      <origin xyz="-0.32 0 0.06" rpy="0 0 0"/>
      <geometry>
        <box size="0.06 0.4 0.02"/>
      </geometry>
      <material name="frame_steel">
        <color rgba="0.6 0.6 0.7 1.0"/>
      </material>
    </visual>
    
    <!-- Side protection rails -->
    <visual>
      <origin xyz="0 0.22 0.06" rpy="0 0 0"/>
      <geometry>
        <box size="0.7 0.04 0.08"/>
      </geometry>
      <material name="safety_yellow">
        <color rgba="1.0 0.9 0.0 1.0"/>
      </material>
    </visual>
    
    <visual>
      <origin xyz="0 -0.22 0.06" rpy="0 0 0"/>
      <geometry>
        <box size="0.7 0.04 0.08"/>
      </geometry>
      <material name="safety_yellow">
        <color rgba="1.0 0.9 0.0 1.0"/>
      </material>
    </visual>
    
    <!-- Battery compartment -->
    <visual>
      <origin xyz="-0.15 0 0.14" rpy="0 0 0"/>
      <geometry>
        <box size="0.25 0.2 0.04"/>
      </geometry>
      <material name="battery_housing">
        <color rgba="0.1 0.1 0.15 1.0"/>
      </material>
    </visual>
    
    <!-- Control electronics housing -->
    <visual>
      <origin xyz="0.15 0 0.14" rpy="0 0 0"/>
      <geometry>
        <box size="0.2 0.15 0.04"/>
      </geometry>
      <material name="electronics_silver">
        <color rgba="0.7 0.7 0.8 1.0"/>
      </material>
    </visual>
    
    <!-- Status LED strip -->
    <visual>
      <origin xyz="0.25 0 0.16" rpy="0 0 0"/>
      <geometry>
        <box size="0.15 0.02 0.005"/>
      </geometry>
      <material name="led_strip_blue">
        <color rgba="0.0 0.5 1.0 1.0"/>
      </material>
    </visual>
    
    <collision>
      <origin xyz="0 0 0.06" rpy="0 0 0"/>
      <geometry>
        <box size="0.7 0.4 0.12"/>
      </geometry>
    </collision>
    <inertial>
      <origin xyz="0 0 0.06" rpy="0 0 0"/>
      <mass value="18.0"/>
      <inertia ixx="0.5" ixy="0" ixz="0" 
               iyy="1.2" iyz="0" 
               izz="1.5"/>
    </inertial>
  </link>

  <!-- Advanced Drive Wheels with Motor Integration -->
  <link name="left_wheel">
    <!-- Main tire with aggressive tread -->
    <visual>
      <origin xyz="0 0 0" rpy="1.57 0 0"/>
      <geometry>
        <cylinder radius="0.125" length="0.06"/>
      </geometry>
      <material name="tire_industrial">
        <color rgba="0.05 0.05 0.05 1.0"/>
      </material>
    </visual>
    
    <!-- Reinforced rim -->
    <visual>
      <origin xyz="0 0 0" rpy="1.57 0 0"/>
      <geometry>
        <cylinder radius="0.1" length="0.065"/>
      </geometry>
      <material name="rim_aluminum">
        <color rgba="0.7 0.7 0.8 1.0"/>
      </material>
    </visual>
    
    <!-- Hub motor housing -->
    <visual>
      <origin xyz="0 0 0" rpy="1.57 0 0"/>
      <geometry>
        <cylinder radius="0.06" length="0.07"/>
      </geometry>
      <material name="motor_housing">
        <color rgba="0.2 0.2 0.3 1.0"/>
      </material>
    </visual>
    
    <!-- Motor cooling fins -->
    <visual>
      <origin xyz="0 0 0.04" rpy="1.57 0 0"/>
      <geometry>
        <cylinder radius="0.08" length="0.005"/>
      </geometry>
      <material name="cooling_fins">
        <color rgba="0.5 0.5 0.6 1.0"/>
      </material>
    </visual>
    
    <visual>
      <origin xyz="0 0 -0.04" rpy="1.57 0 0"/>
      <geometry>
        <cylinder radius="0.08" length="0.005"/>
      </geometry>
      <material name="cooling_fins">
        <color rgba="0.5 0.5 0.6 1.0"/>
      </material>
    </visual>
    
    <!-- Wheel encoder -->
    <visual>
      <origin xyz="0 0 0.038" rpy="1.57 0 0"/>
      <geometry>
        <cylinder radius="0.04" length="0.008"/>
      </geometry>
      <material name="encoder_gold">
        <color rgba="0.8 0.7 0.2 1.0"/>
      </material>
    </visual>
    
    <collision>
      <origin xyz="0 0 0" rpy="1.57 0 0"/>
      <geometry>
        <cylinder radius="0.125" length="0.06"/>
      </geometry>
    </collision>
    <inertial>
      <origin xyz="0 0 0" rpy="0 0 0"/>
      <mass value="3.5"/>
      <inertia ixx="0.03" ixy="0" ixz="0" 
               iyy="0.03" iyz="0" 
               izz="0.03"/>
    </inertial>
  </link>

  <!-- Right wheel - identical to left -->
  <link name="right_wheel">
    <visual>
      <origin xyz="0 0 0" rpy="1.57 0 0"/>
      <geometry>
        <cylinder radius="0.125" length="0.06"/>
      </geometry>
      <material name="tire_industrial">
        <color rgba="0.05 0.05 0.05 1.0"/>
      </material>
    </visual>
    <visual>
      <origin xyz="0 0 0" rpy="1.57 0 0"/>
      <geometry>
        <cylinder radius="0.1" length="0.065"/>
      </geometry>
      <material name="rim_aluminum">
        <color rgba="0.7 0.7 0.8 1.0"/>
      </material>
    </visual>
    <visual>
      <origin xyz="0 0 0" rpy="1.57 0 0"/>
      <geometry>
        <cylinder radius="0.06" length="0.07"/>
      </geometry>
      <material name="motor_housing">
        <color rgba="0.2 0.2 0.3 1.0"/>
      </material>
    </visual>
    <visual>
      <origin xyz="0 0 0.04" rpy="1.57 0 0"/>
      <geometry>
        <cylinder radius="0.08" length="0.005"/>
      </geometry>
      <material name="cooling_fins">
        <color rgba="0.5 0.5 0.6 1.0"/>
      </material>
    </visual>
    <visual>
      <origin xyz="0 0 -0.04" rpy="1.57 0 0"/>
      <geometry>
        <cylinder radius="0.08" length="0.005"/>
      </geometry>
      <material name="cooling_fins">
        <color rgba="0.5 0.5 0.6 1.0"/>
      </material>
    </visual>
    <visual>
      <origin xyz="0 0 0.038" rpy="1.57 0 0"/>
      <geometry>
        <cylinder radius="0.04" length="0.008"/>
      </geometry>
      <material name="encoder_gold">
        <color rgba="0.8 0.7 0.2 1.0"/>
      </material>
    </visual>
    <collision>
      <origin xyz="0 0 0" rpy="1.57 0 0"/>
      <geometry>
        <cylinder radius="0.125" length="0.06"/>
      </geometry>
    </collision>
    <inertial>
      <origin xyz="0 0 0" rpy="0 0 0"/>
      <mass value="3.5"/>
      <inertia ixx="0.03" ixy="0" ixz="0" 
               iyy="0.03" iyz="0" 
               izz="0.03"/>
    </inertial>
  </link>

  <!-- Professional Lifting Mechanism Base -->
  <link name="lift_base">
    <!-- Main lift tower structure -->
    <visual>
      <origin xyz="0 0 0.08" rpy="0 0 0"/>
      <geometry>
        <box size="0.25 0.25 0.16"/>
      </geometry>
      <material name="lift_orange">
        <color rgba="1.0 0.5 0.1 1.0"/>
      </material>
    </visual>
    
    <!-- Hydraulic cylinder housings -->
    <visual>
      <origin xyz="0.08 0.08 0.08" rpy="0 0 0"/>
      <geometry>
        <cylinder radius="0.025" length="0.16"/>
      </geometry>
      <material name="hydraulic_steel">
        <color rgba="0.4 0.4 0.5 1.0"/>
      </material>
    </visual>
    
    <visual>
      <origin xyz="-0.08 0.08 0.08" rpy="0 0 0"/>
      <geometry>
        <cylinder radius="0.025" length="0.16"/>
      </geometry>
      <material name="hydraulic_steel">
        <color rgba="0.4 0.4 0.5 1.0"/>
      </material>
    </visual>
    
    <visual>
      <origin xyz="0.08 -0.08 0.08" rpy="0 0 0"/>
      <geometry>
        <cylinder radius="0.025" length="0.16"/>
      </geometry>
      <material name="hydraulic_steel">
        <color rgba="0.4 0.4 0.5 1.0"/>
      </material>
    </visual>
    
    <visual>
      <origin xyz="-0.08 -0.08 0.08" rpy="0 0 0"/>
      <geometry>
        <cylinder radius="0.025" length="0.16"/>
      </geometry>
      <material name="hydraulic_steel">
        <color rgba="0.4 0.4 0.5 1.0"/>
      </material>
    </visual>
    
    <!-- Guide rails -->
    <visual>
      <origin xyz="0.12 0 0.08" rpy="0 0 0"/>
      <geometry>
        <box size="0.02 0.03 0.16"/>
      </geometry>
      <material name="guide_rail">
        <color rgba="0.6 0.6 0.7 1.0"/>
      </material>
    </visual>
    
    <visual>
      <origin xyz="-0.12 0 0.08" rpy="0 0 0"/>
      <geometry>
        <box size="0.02 0.03 0.16"/>
      </geometry>
      <material name="guide_rail">
        <color rgba="0.6 0.6 0.7 1.0"/>
      </material>
    </visual>
    
    <!-- Safety markings -->
    <visual>
      <origin xyz="0 0.13 0.08" rpy="0 0 0"/>
      <geometry>
        <box size="0.2 0.02 0.12"/>
      </geometry>
      <material name="safety_stripe">
        <color rgba="1.0 1.0 0.0 1.0"/>
      </material>
    </visual>
    
    <visual>
      <origin xyz="0 -0.13 0.08" rpy="0 0 0"/>
      <geometry>
        <box size="0.2 0.02 0.12"/>
      </geometry>
      <material name="safety_stripe">
        <color rgba="1.0 1.0 0.0 1.0"/>
      </material>
    </visual>
    
    <collision>
      <origin xyz="0 0 0.08" rpy="0 0 0"/>
      <geometry>
        <box size="0.25 0.25 0.16"/>
      </geometry>
    </collision>
    <inertial>
      <origin xyz="0 0 0.08" rpy="0 0 0"/>
      <mass value="8.5"/>
      <inertia ixx="0.08" ixy="0" ixz="0" 
               iyy="0.08" iyz="0" 
               izz="0.12"/>
    </inertial>
  </link>

  <!-- Advanced Lifting Platform -->
  <link name="lift_platform">
    <!-- Main platform deck -->
    <visual>
      <origin xyz="0 0 0.025" rpy="0 0 0"/>
      <geometry>
        <box size="0.35 0.35 0.05"/>
      </geometry>
      <material name="platform_green">
        <color rgba="0.2 0.8 0.3 1.0"/>
      </material>
    </visual>
    
    <!-- Anti-slip surface pattern -->
    <visual>
      <origin xyz="0 0 0.052" rpy="0 0 0"/>
      <geometry>
        <box size="0.33 0.33 0.004"/>
      </geometry>
      <material name="anti_slip">
        <color rgba="0.1 0.1 0.1 1.0"/>
      </material>
    </visual>
    
    <!-- Load securing points -->
    <visual>
      <origin xyz="0.12 0.12 0.06" rpy="0 0 0"/>
      <geometry>
        <cylinder radius="0.008" length="0.012"/>
      </geometry>
      <material name="tie_down">
        <color rgba="0.6 0.6 0.7 1.0"/>
      </material>
    </visual>
    
    <visual>
      <origin xyz="-0.12 0.12 0.06" rpy="0 0 0"/>
      <geometry>
        <cylinder radius="0.008" length="0.012"/>
      </geometry>
      <material name="tie_down">
        <color rgba="0.6 0.6 0.7 1.0"/>
      </material>
    </visual>
    
    <visual>
      <origin xyz="0.12 -0.12 0.06" rpy="0 0 0"/>
      <geometry>
        <cylinder radius="0.008" length="0.012"/>
      </geometry>
      <material name="tie_down">
        <color rgba="0.6 0.6 0.7 1.0"/>
      </material>
    </visual>
    
    <visual>
      <origin xyz="-0.12 -0.12 0.06" rpy="0 0 0"/>
      <geometry>
        <cylinder radius="0.008" length="0.012"/>
      </geometry>
      <material name="tie_down">
        <color rgba="0.6 0.6 0.7 1.0"/>
      </material>
    </visual>
    
    <!-- Hydraulic pistons -->
    <visual>
      <origin xyz="0.08 0.08 -0.05" rpy="0 0 0"/>
      <geometry>
        <cylinder radius="0.015" length="0.1"/>
      </geometry>
      <material name="piston_chrome">
        <color rgba="0.8 0.8 0.9 1.0"/>
      </material>
    </visual>
    
    <visual>
      <origin xyz="-0.08 0.08 -0.05" rpy="0 0 0"/>
      <geometry>
        <cylinder radius="0.015" length="0.1"/>
      </geometry>
      <material name="piston_chrome">
        <color rgba="0.8 0.8 0.9 1.0"/>
      </material>
    </visual>
    
    <visual>
      <origin xyz="0.08 -0.08 -0.05" rpy="0 0 0"/>
      <geometry>
        <cylinder radius="0.015" length="0.1"/>
      </geometry>
      <material name="piston_chrome">
        <color rgba="0.8 0.8 0.9 1.0"/>
      </material>
    </visual>
    
    <visual>
      <origin xyz="-0.08 -0.08 -0.05" rpy="0 0 0"/>
      <geometry>
        <cylinder radius="0.015" length="0.1"/>
      </geometry>
      <material name="piston_chrome">
        <color rgba="0.8 0.8 0.9 1.0"/>
      </material>
    </visual>
    
    <!-- Safety perimeter lighting -->
    <visual>
      <origin xyz="0.18 0 0.03" rpy="0 1.57 0"/>
      <geometry>
        <cylinder radius="0.005" length="0.01"/>
      </geometry>
      <material name="safety_led">
        <color rgba="1.0 0.0 0.0 1.0"/>
      </material>
    </visual>
    
    <visual>
      <origin xyz="-0.18 0 0.03" rpy="0 1.57 0"/>
      <geometry>
        <cylinder radius="0.005" length="0.01"/>
      </geometry>
      <material name="safety_led">
        <color rgba="1.0 0.0 0.0 1.0"/>
      </material>
    </visual>
    
    <visual>
      <origin xyz="0 0.18 0.03" rpy="1.57 0 0"/>
      <geometry>
        <cylinder radius="0.005" length="0.01"/>
      </geometry>
      <material name="safety_led">
        <color rgba="1.0 0.0 0.0 1.0"/>
      </material>
    </visual>
    
    <visual>
      <origin xyz="0 -0.18 0.03" rpy="1.57 0 0"/>
      <geometry>
        <cylinder radius="0.005" length="0.01"/>
      </geometry>
      <material name="safety_led">
        <color rgba="1.0 0.0 0.0 1.0"/>
      </material>
    </visual>
    
    <collision>
      <origin xyz="0 0 0.025" rpy="0 0 0"/>
      <geometry>
        <box size="0.35 0.35 0.05"/>
      </geometry>
    </collision>
    <inertial>
      <origin xyz="0 0 0.025" rpy="0 0 0"/>
      <mass value="4.5"/>
      <inertia ixx="0.06" ixy="0" ixz="0" 
               iyy="0.06" iyz="0" 
               izz="0.1"/>
    </inertial>
  </link>

  <!-- Advanced Sensor Package -->
  <link name="laser_scanner">
    <visual>
      <origin xyz="0 0 0.03" rpy="0 0 0"/>
      <geometry>
        <cylinder radius="0.05" length="0.06"/>
      </geometry>
      <material name="lidar_black">
        <color rgba="0.05 0.05 0.08 1.0"/>
      </material>
    </visual>
    
    <!-- Spinning assembly -->
    <visual>
      <origin xyz="0 0 0.065" rpy="0 0 0"/>
      <geometry>
        <cylinder radius="0.04" length="0.01"/>
      </geometry>
      <material name="lidar_mirror">
        <color rgba="0.8 0.8 0.9 1.0"/>
      </material>
    </visual>
    
    <collision>
      <origin xyz="0 0 0.03" rpy="0 0 0"/>
      <geometry>
        <cylinder radius="0.05" length="0.06"/>
      </geometry>
    </collision>
    <inertial>
      <origin xyz="0 0 0.03" rpy="0 0 0"/>
      <mass value="0.8"/>
      <inertia ixx="0.002" ixy="0" ixz="0" 
               iyy="0.002" iyz="0" 
               izz="0.002"/>
    </inertial>
  </link>

  <!-- Emergency Stop System -->
  <link name="emergency_stop">
    <visual>
      <origin xyz="0 0 0.015" rpy="0 0 0"/>
      <geometry>
        <cylinder radius="0.04" length="0.03"/>
      </geometry>
      <material name="emergency_red">
        <color rgba="1.0 0.0 0.0 1.0"/>
      </material>
    </visual>
    
    <collision>
      <origin xyz="0 0 0.015" rpy="0 0 0"/>
      <geometry>
        <cylinder radius="0.04" length="0.03"/>
      </geometry>
    </collision>
    <inertial>
      <origin xyz="0 0 0.015" rpy="0 0 0"/>
      <mass value="0.1"/>
      <inertia ixx="0.0001" ixy="0" ixz="0" 
               iyy="0.0001" iyz="0" 
               izz="0.0001"/>
    </inertial>
  </link>

  <!-- JOINTS SECTION -->

  <!-- High-Performance Wheel Joints -->
  <joint name="left_wheel_joint" type="continuous">
    <parent link="base_link"/>
    <child link="left_wheel"/>
    <origin xyz="0 0.22 0" rpy="0 0 0"/>
    <axis xyz="0 1 0"/>
    <dynamics damping="0.3" friction="0.2"/>
  </joint>

  <joint name="right_wheel_joint" type="continuous">
    <parent link="base_link"/>
    <child link="right_wheel"/>
    <origin xyz="0 -0.22 0" rpy="0 0 0"/>
    <axis xyz="0 1 0"/>
    <dynamics damping="0.3" friction="0.2"/>
  </joint>

  <!-- Lift Base Mount -->
  <joint name="lift_base_joint" type="fixed">
    <parent link="base_link"/>
    <child link="lift_base"/>
    <origin xyz="0 0 0.12" rpy="0 0 0"/>
  </joint>

  <!-- Professional Lifting System -->
  <joint name="lift_joint" type="prismatic">
    <parent link="lift_base"/>
    <child link="lift_platform"/>
    <origin xyz="0 0 0.16" rpy="0 0 0"/>
    <axis xyz="0 0 1"/>
    <limit lower="0" upper="0.5" effort="500" velocity="0.8"/>
    <dynamics damping="0.5" friction="0.3"/>
  </joint>

  <!-- Sensor Mounts -->
  <joint name="laser_scanner_joint" type="fixed">
    <parent link="base_link"/>
    <child link="laser_scanner"/>
    <origin xyz="0.3 0 0.18" rpy="0 0 0"/>
  </joint>

  <joint name="emergency_stop_joint" type="fixed">
    <parent link="base_link"/>
    <child link="emergency_stop"/>
    <origin xyz="0.25 0.15 0.18" rpy="0 0 0"/>
  </joint>

</robot>